Workbook

Sheet ВИС-2026
C1: 46038
E2: ПРАЙС-ЛИСТ РЕХАУ ВИС EA 2026
B3: НДС | C3: 1.22
E5: 0 | F5: Основная скидка / Grundrabatt:
E7: 0 | F7: Скидка за оснащение склада или объектная скидка / Lagererstausstattungsrabatt bzw.Objektrabatt::
E9: 0 | F9: Скидка за предоплату / Skonto: | AK9: 0.24
AK10: 0.2
E11: 0 | F11: Надбавка / Logistikkostenaufschlag: | AK11: 100
B13: Z - Планируется замена артикула; N = Новый артикул; D = Выводится из программы поставок.
C14: Программа | D14: Прежний материал | E14: Актуальный материал | F14: Наименование | G14: Кол-во | H14: Ед. изм. | I14: Единица поставки | J14: Цена брутто ЕВРО без НДС | K14: Цена брутто ЕВРО с НДС | L14: Сумма брутто ЕВРО с НДС | M14: Цена нетто ЕВРО без НДС | N14: Сумма нетто ЕВРО без НДС | O14: Цена нетто ЕВРО с НДС | P14: Сумма нетто ЕВРО с НДС | R14: РРЦ, РУБ С НДС | AK14: РРЦ, РУБ С НДС
C16: RAUTITAN | F16: 1.1.1. Трубы и комплектующие на водоснабжение и отопление
A17: D = Выводится из программы поставок. Распродаются остатки на складе. | B17: АКЦИЯ! РАСПРОДАЖА | C17: RAUTITAN | E17: 11234081005 | F17: Универсальн.труба RAUTITAN stabil PLATINUM 32х4,7 мм, прям. отрезки 5м | H17: м | I17: 5 | J17: 5.5 | K17: =ROUND((J17*$C$3),2) -> 6.71 | L17: =K17*G17 -> 0 | M17: =J17*(1-$E$5-$E$7)*(1-$E$9)*(1+$E$11) -> 5.5 | N17: =M17*G17 -> 0 | O17: =ROUND((M17*$C$3),2) -> 6.71 | P17: =O17*G17 -> 0 | R17: =ROUND(AK17,0) -> 537 | AK17: =K17*$AK$11*(1-$AK$10) -> 536.8
A18: D = Выводится из программы поставок. Распродаются остатки на складе. | B18: АКЦИЯ! РАСПРОДАЖА | C18: RAUTITAN | E18: 11301011005 | F18: Универсальн.труба RAUTITAN stabil 32х4,7 мм, прям.отрезки 5м | H18: м | I18: 25 | J18: 5.15 | K18: =ROUND((J18*$C$3),2) -> 6.28 | L18: =K18*G18 -> 0 | M18: =J18*(1-$E$5-$E$7)*(1-$E$9)*(1+$E$11) -> 5.15 | N18: =M18*G18 -> 0 | O18: =ROUND((M18*$C$3),2) -> 6.28 | P18: =O18*G18 -> 0 | R18: =ROUND(AK18,0) -> 502 | AK18: =K18*$AK$11*(1-$AK$10) -> 502.4
B20: N | C20: RAUTITAN | D20: 11301211100 | E20: 11301213100 | F20: Универсальн.труба РЕХАУ STABIL 16,2х2,6 мм, бухта 100 м | H20: м | I20: 100 | J20: 3.89 | K20: =ROUND((J20*$C$3),2) -> 4.75 | L20: =K20*G20 -> 0 | M20: =J20*(1-$E$5-$E$7)*(1-$E$9)*(1+$E$11) -> 3.89 | N20: =M20*G20 -> 0 | O20: =ROUND((M20*$C$3),2) -> 4.75 | P20: =O20*G20 -> 0 | R20: =ROUND(AK20,0) -> 380 | AK20: =K20*$AK$11*(1-$AK$10) -> 380
B21: N | C21: RAUTITAN | D21: 11301311100 | E21: 11301313100 | F21: Универсальн.труба РЕХАУ STABIL 20х2,9 мм, бухта 100 м | H21: м | I21: 100 | J21: 5.53 | K21: =ROUND((J21*$C$3),2) -> 6.75 | L21: =K21*G21 -> 0 | M21: =J21*(1-$E$5-$E$7)*(1-$E$9)*(1+$E$11) -> 5.53 | N21: =M21*G21 -> 0 | O21: =ROUND((M21*$C$3),2) -> 6.75 | P21: =O21*G21 -> 0 | R21: =ROUND(AK21,0) -> 540 | AK21: =K21*$AK$11*(1-$AK$10) -> 540
B22: N | C22: RAUTITAN | D22: 11301411050 | E22: 11301413050 | F22: Универсальн.труба РЕХАУ STABIL 25х3,7 мм, бухта 50 м | H22: м | I22: 50 | J22: 9.97 | K22: =ROUND((J22*$C$3),2) -> 12.16 | L22: =K22*G22 -> 0 | M22: =J22*(1-$E$5-$E$7)*(1-$E$9)*(1+$E$11) -> 9.97 | N22: =M22*G22 -> 0 | O22: =ROUND((M22*$C$3),2) -> 12.16 | P22: =O22*G22 -> 0 | R22: =ROUND(AK22,0) -> 973 | AK22: =K22*$AK$11*(1-$AK$10) -> 972.8
B23: N | C23: RAUTITAN | D23: 11301511025 | E23: 11301513025 | F23: Универсальн.труба РЕХАУ STABIL 32х4,7 мм, бухта 25 м | H23: м | I23: 25 | J23: 11.76 | K23: =ROUND((J23*$C$3),2) -> 14.35 | L23: =K23*G23 -> 0 | M23: =J23*(1-$E$5-$E$7)*(1-$E$9)*(1+$E$11) -> 11.76 | N23: =M23*G23 -> 0 | O23: =ROUND((M23*$C$3),2) -> 14.35 | P23: =O23*G23 -> 0 | R23: =ROUND(AK23,0) -> 1148 | AK23: =K23*$AK$11*(1-$AK$10) -> 1148
B24: N | C24: RAUTITAN | D24: 11301111005 | E24: 11301113005 | F24: Универсальн.труба РЕХАУ STABIL 40х6,0 мм, прям.отрезки 5м | H24: м | I24: 15 | J24: 31.19 | K24: =ROUND((J24*$C$3),2) -> 38.05 | L24: =K24*G24 -> 0 | M24: =J24*(1-$E$5-$E$7)*(1-$E$9)*(1+$E$11) -> 31.19 | N24: =M24*G24 -> 0 | O24: =ROUND((M24*$C$3),2) -> 38.05 | P24: =O24*G24 -> 0 | R24: =ROUND(AK24,0) -> 3044 | AK24: =K24*$AK$11*(1-$AK$10) -> 3044
B26: N | C26: RAUTITAN | D26: 11303701100 | E26: 11303703100 | F26: Универсальн.труба РЕХАУ FLEX 16x2,2, бухта 100м | H26: м | I26: 100 | J26: 2.04 | K26: =ROUND((J26*$C$3),2) -> 2.49 | L26: =K26*G26 -> 0 | M26: =J26*(1-$E$5-$E$7)*(1-$E$9)*(1+$E$11) -> 2.04 | N26: =M26*G26 -> 0 | O26: =ROUND((M26*$C$3),2) -> 2.49 | P26: =O26*G26 -> 0 | R26: =ROUND(AK26,0) -> 199 | AK26: =K26*$AK$11*(1-$AK$10) -> 199.2
B27: N | C27: RAUTITAN | D27: 11303801100 | E27: 11303803100 | F27: Универсальн.труба РЕХАУ FLEX 20x2,8, бухта 100м | H27: м | I27: 100 | J27: 3.05 | K27: =ROUND((J27*$C$3),2) -> 3.72 | L27: =K27*G27 -> 0 | M27: =J27*(1-$E$5-$E$7)*(1-$E$9)*(1+$E$11) -> 3.05 | N27: =M27*G27 -> 0 | O27: =ROUND((M27*$C$3),2) -> 3.72 | P27: =O27*G27 -> 0 | R27: =ROUND(AK27,0) -> 298 | AK27: =K27*$AK$11*(1-$AK$10) -> 297.6
B28: N | C28: RAUTITAN | D28: 11303901050 | E28: 11303903050 | F28: Универсальн.труба РЕХАУ FLEX 25x3,5, бухта 50м | H28: м | I28: 50 | J28: 4.73 | K28: =ROUND((J28*$C$3),2) -> 5.77 | L28: =K28*G28 -> 0 | M28: =J28*(1-$E$5-$E$7)*(1-$E$9)*(1+$E$11) -> 4.73 | N28: =M28*G28 -> 0 | O28: =ROUND((M28*$C$3),2) -> 5.77 | P28: =O28*G28 -> 0 | R28: =ROUND(AK28,0) -> 462 | AK28: =K28*$AK$11*(1-$AK$10) -> 461.6
B29: N | C29: RAUTITAN | D29: 11304001050 | E29: 11304003050 | F29: Универсальн.труба РЕХАУ FLEX 32x4,4, бухта 50м | H29: м | I29: 50 | J29: 7.69 | K29: =ROUND((J29*$C$3),2) -> 9.38 | L29: =K29*G29 -> 0 | M29: =J29*(1-$E$5-$E$7)*(1-$E$9)*(1+$E$11) -> 7.69 | N29: =M29*G29 -> 0 | O29: =ROUND((M29*$C$3),2) -> 9.38 | P29: =O29*G29 -> 0 | R29: =ROUND(AK29,0) -> 750 | AK29: =K29*$AK$11*(1-$AK$10) -> 750.4
B30: N | C30: RAUTITAN | D30: 11304103006 | E30: 11304113006 | F30: Универсальн.труба РЕХАУ FLEX 40x5,5, прям.отрезки 6м | H30: м | I30: 12 | J30: 14.92 | K30: =ROUND((J30*$C$3),2) -> 18.2 | L30: =K30*G30 -> 0 | M30: =J30*(1-$E$5-$E$7)*(1-$E$9)*(1+$E$11) -> 14.92 | N30: =M30*G30 -> 0 | O30: =ROUND((M30*$C$3),2) -> 18.2 | P30: =O30*G30 -> 0 | R30: =ROUND(AK30,0) -> 1432 | AK30: 1432
B31: N | C31: RAUTITAN | D31: 11304203006 | E31: 11304213006 | F31: Универсальн.труба РЕХАУ FLEX 50x6,9, прям.отрезки 6м | H31: м | I31: 6 | J31: 19.63 | K31: =ROUND((J31*$C$3),2) -> 23.95 | L31: =K31*G31 -> 0 | M31: =J31*(1-$E$5-$E$7)*(1-$E$9)*(1+$E$11) -> 19.63 | N31: =M31*G31 -> 0 | O31: =ROUND((M31*$C$3),2) -> 23.95 | P31: =O31*G31 -> 0 | R31: =ROUND(AK31,0) -> 1916 | AK31: =K31*$AK$11*(1-$AK$10) -> 1916
B32: N | C32: RAUTITAN | D32: 11304303006 | E32: 11304313006 | F32: Универсальн.труба РЕХАУ FLEX 63x8,6, прям.отрезки 6м | H32: м | I32: 6 | J32: 28.97 | K32: =ROUND((J32*$C$3),2) -> 35.34 | L32: =K32*G32 -> 0 | M32: =J32*(1-$E$5-$E$7)*(1-$E$9)*(1+$E$11) -> 28.97 | N32: =M32*G32 -> 0 | O32: =ROUND((M32*$C$3),2) -> 35.34 | P32: =O32*G32 -> 0 | R32: =ROUND(AK32,0) -> 2827 | AK32: =K32*$AK$11*(1-$AK$10) -> 2827.2
B34: N | C34: RAUTITAN | D34: 11360421120 | E34: 11360423120 | F34: Отоп. труба РЕХАУ PINK 16х2,2 мм, бухта 120 м | H34: м | I34: 120 | J34: 1.95 | K34: =ROUND((J34*$C$3),2) -> 2.38 | L34: =K34*G34 -> 0 | M34: =J34*(1-$E$5-$E$7)*(1-$E$9)*(1+$E$11) -> 1.95 | N34: =M34*G34 -> 0 | O34: =ROUND((M34*$C$3),2) -> 2.38 | P34: =O34*G34 -> 0 | R34: =ROUND(AK34,0) -> 190 | AK34: =K34*$AK$11*(1-$AK$10) -> 190.4
B35: N | C35: RAUTITAN | D35: 11360521120 | E35: 11360523120 | F35: Отоп. труба РЕХАУ PINK 20х2,8 мм, бухта 120 м | H35: м | I35: 120 | J35: 2.84 | K35: =ROUND((J35*$C$3),2) -> 3.46 | L35: =K35*G35 -> 0 | M35: =J35*(1-$E$5-$E$7)*(1-$E$9)*(1+$E$11) -> 2.84 | N35: =M35*G35 -> 0 | O35: =ROUND((M35*$C$3),2) -> 3.46 | P35: =O35*G35 -> 0 | R35: =ROUND(AK35,0) -> 277 | AK35: =K35*$AK$11*(1-$AK$10) -> 276.8
B36: N | C36: RAUTITAN | D36: 11360621050 | E36: 11360623050 | F36: Отоп. труба РЕХАУ PINK 25х3,5 мм, бухта 50 м | H36: м | I36: 50 | J36: 4.4 | K36: =ROUND((J36*$C$3),2) -> 5.37 | L36: =K36*G36 -> 0 | M36: =J36*(1-$E$5-$E$7)*(1-$E$9)*(1+$E$11) -> 4.4 | N36: =M36*G36 -> 0 | O36: =ROUND((M36*$C$3),2) -> 5.37 | P36: =O36*G36 -> 0 | R36: =ROUND(AK36,0) -> 430 | AK36: =K36*$AK$11*(1-$AK$10) -> 429.6
B37: N | C37: RAUTITAN | D37: 11360721050 | E37: 11360723050 | F37: Отоп. труба РЕХАУ PINK 32х4,4 мм, бухта 50 м | H37: м | I37: 50 | J37: 7.15 | K37: =ROUND((J37*$C$3),2) -> 8.72 | L37: =K37*G37 -> 0 | M37: =J37*(1-$E$5-$E$7)*(1-$E$9)*(1+$E$11) -> 7.15 | N37: =M37*G37 -> 0 | O37: =ROUND((M37*$C$3),2) -> 8.72 | P37: =O37*G37 -> 0 | R37: =ROUND(AK37,0) -> 698 | AK37: =K37*$AK$11*(1-$AK$10) -> 697.6
B39: N | C39: RAUTITAN | D39: 11331691200 | E39: 11331703200 | F39: Универсальн. объектная труба РЕХАУ BLACK 16х2,2 мм, бухта 200 м | H39: м | I39: 200 | J39: по запросу
B40: N | C40: RAUTITAN | D40: 11331791180 | E40: 11331803180 | F40: Универсальн. объектная труба РЕХАУ BLACK 20х2,8 мм, бухта 180 м | H40: м | I40: 180 | J40: по запросу
B41: N | C41: RAUTITAN | D41: 11331891100 | E41: 11331903100 | F41: Универсальн. объектная труба РЕХАУ BLACK 25х3,5 мм, бухта 100 м | H41: м | I41: 100 | J41: по запросу
B43: D | C43: RAUTITAN | D43: 11331691200 | E43: 11331693200 | F43: Отоп.труба РЕХАУ BLACK 16х2,2 мм, бухта 200 м | H43: м | I43: 2600 | J43: 1.58 | K43: =ROUND((J43*$C$3),2) -> 1.93 | L43: =K43*G43 -> 0 | M43: =J43*(1-$E$5-$E$7)*(1-$E$9)*(1+$E$11) -> 1.58 | N43: =M43*G43 -> 0 | O43: =ROUND((M43*$C$3),2) -> 1.93 | P43: =O43*G43 -> 0 | AK43: =K43*$AK$11*(1-$AK$10) -> 154.4
B44: D | C44: RAUTITAN | D44: 11331791180 | E44: 11331793180 | F44: Отоп.труба РЕХАУ BLACK 20х2,8 мм, бухта 180 м | H44: м | I44: 1440 | J44: 2.16 | K44: =ROUND((J44*$C$3),2) -> 2.64 | L44: =K44*G44 -> 0 | M44: =J44*(1-$E$5-$E$7)*(1-$E$9)*(1+$E$11) -> 2.16 | N44: =M44*G44 -> 0 | O44: =ROUND((M44*$C$3),2) -> 2.64 | P44: =O44*G44 -> 0 | AK44: =K44*$AK$11*(1-$AK$10) -> 211.2
B45: D | C45: RAUTITAN | D45: 11331891100 | E45: 11331893100 | F45: Отоп.труба РЕХАУ BLACK 25х3,5 мм, бухта 100 м | H45: м | I45: 800 | J45: 3.32 | K45: =ROUND((J45*$C$3),2) -> 4.05 | L45: =K45*G45 -> 0 | M45: =J45*(1-$E$5-$E$7)*(1-$E$9)*(1+$E$11) -> 3.32 | N45: =M45*G45 -> 0 | O45: =ROUND((M45*$C$3),2) -> 4.05 | P45: =O45*G45 -> 0 | AK45: =K45*$AK$11*(1-$AK$10) -> 324
B47: N | C47: RAUTITAN | D47: 11380331001 | E47: 11380333001 | F47: Фиксирующий желоб РЕХАУ для ПЭ-трубы 16/17 | H47: м | I47: 30 | J47: 2.13 | K47: =ROUND((J47*$C$3),2) -> 2.6 | L47: =K47*G47 -> 0 | M47: =J47*(1-$E$5-$E$7)*(1-$E$9)*(1+$E$11) -> 2.13 | N47: =M47*G47 -> 0 | O47: =ROUND((M47*$C$3),2) -> 2.6 | P47: =O47*G47 -> 0 | R47: =ROUND(AK47,0) -> 208 | AK47: =K47*$AK$11*(1-$AK$10) -> 208
B48: N | C48: RAUTITAN | D48: 11380431001 | E48: 11380433001 | F48: Фиксирующий желоб РЕХАУ для ПЭ-трубы 20 | H48: м | I48: 30 | J48: 2.31 | K48: =ROUND((J48*$C$3),2) -> 2.82 | L48: =K48*G48 -> 0 | M48: =J48*(1-$E$5-$E$7)*(1-$E$9)*(1+$E$11) -> 2.31 | N48: =M48*G48 -> 0 | O48: =ROUND((M48*$C$3),2) -> 2.82 | P48: =O48*G48 -> 0 | R48: =ROUND(AK48,0) -> 226 | AK48: =K48*$AK$11*(1-$AK$10) -> 225.6
B49: N | C49: RAUTITAN | D49: 11380531001 | E49: 11380533001 | F49: Фиксирующий желоб РЕХАУ для ПЭ-трубы 25 | H49: м | I49: 30 | J49: 3.05 | K49: =ROUND((J49*$C$3),2) -> 3.72 | L49: =K49*G49 -> 0 | M49: =J49*(1-$E$5-$E$7)*(1-$E$9)*(1+$E$11) -> 3.05 | N49: =M49*G49 -> 0 | O49: =ROUND((M49*$C$3),2) -> 3.72 | P49: =O49*G49 -> 0 | R49: =ROUND(AK49,0) -> 298 | AK49: =K49*$AK$11*(1-$AK$10) -> 297.6
B50: N | C50: RAUTITAN | D50: 11380631001 | E50: 11380633001 | F50: Фиксирующий желоб РЕХАУ для ПЭ-трубы 32 | H50: м | I50: 30 | J50: 3.76 | K50: =ROUND((J50*$C$3),2) -> 4.59 | L50: =K50*G50 -> 0 | M50: =J50*(1-$E$5-$E$7)*(1-$E$9)*(1+$E$11) -> 3.76 | N50: =M50*G50 -> 0 | O50: =ROUND((M50*$C$3),2) -> 4.59 | P50: =O50*G50 -> 0 | R50: =ROUND(AK50,0) -> 367 | AK50: =K50*$AK$11*(1-$AK$10) -> 367.2
B51: N | C51: RAUTITAN | D51: 11380731001 | E51: 11380733001 | F51: Фиксирующий желоб РЕХАУ для ПЭ-трубы 40 | H51: м | I51: 15 | J51: 5.73 | K51: =ROUND((J51*$C$3),2) -> 6.99 | L51: =K51*G51 -> 0 | M51: =J51*(1-$E$5-$E$7)*(1-$E$9)*(1+$E$11) -> 5.73 | N51: =M51*G51 -> 0 | O51: =ROUND((M51*$C$3),2) -> 6.99 | P51: =O51*G51 -> 0 | R51: =ROUND(AK51,0) -> 559 | AK51: =K51*$AK$11*(1-$AK$10) -> 559.2
...

Sheet Шаблон КП
C3: ПРОЕКТ
C4: СИСТЕМА
C5: Дата
N6: Расчет маржинальности/наценки дистрибьютера
C7: Скидка на объект | E7: Скидка | N7: 0 | O7: Скидка за предоплату / Skonto
C8: Курс ЕВРО | E8: РУБ | N8: 0 | O8: Скидка дистрибьютера
N9: =((1-D7)-((1-N8))*(1-N7))/((1-N8)*(1-N7)) -> 0 | O9: Наценка
C10: НДС | D10: 1.22 | N10: =((1-D7)-((1-N8))*(1-N7))/(1-D7) -> 0 | O10: Маржа,%
N11: =M1095*N10 -> 0 | O11: Маржа, руб
B12: Z - Планируется замена артикула; N = Новый артикул; D = Выводится из программы поставок.
C13: Программа | D13: Актуальный материал | E13: Наименование | F13: Ед. изм. | G13: Кол-во | H13: Цена брутто ЕВРО с НДС | I13: Сумма брутто ЕВРО с НДС | J13: Цена нетто ЕВРО с НДС | K13: Сумма нетто ЕВРО с НДС | L13: Цена нетто руб с НДС | M13: Сумма нетто руб с НДС
C15: RAUTITAN | E15: 1.1.1. Трубы и комплектующие на водоснабжение и отопление
A16: D = Выводится из программы поставок. Распродаются остатки на складе. | B16: АКЦИЯ! РАСПРОДАЖА | C16: RAUTITAN | D16: 11234081005 | E16: =IFERROR(VLOOKUP(D16,'ВИС-2026'!$E$17:$H$2115,2,0),"") -> Универсальн.труба RAUTITAN stabil PLATINUM 32х4,7 мм, прям. отрезки 5м | F16: =IFERROR(VLOOKUP(D16,'ВИС-2026'!$E$17:$H$2115,4,0),"") -> м | H16: =IFERROR(VLOOKUP(D16,'ВИС-2026'!$E$17:$K$2649,7,0),"") -> 6.71 | I16: =IFERROR(H16*G16,"") -> 0 | J16: =IFERROR((IF(H16="","",H16-H16*$D$7)),"") -> 6.71 | K16: =IFERROR(J16*G16, "") -> 0 | L16: =IFERROR(J16*$D$8, "") -> 0 | M16: =IFERROR(L16*G16, "") -> 0
A17: D = Выводится из программы поставок. Распродаются остатки на складе. | B17: АКЦИЯ! РАСПРОДАЖА | C17: RAUTITAN | D17: 11301011005 | E17: =IFERROR(VLOOKUP(D17,'ВИС-2026'!$E$17:$H$2115,2,0),"") -> Универсальн.труба RAUTITAN stabil 32х4,7 мм, прям.отрезки 5м | F17: =IFERROR(VLOOKUP(D17,'ВИС-2026'!$E$17:$H$2115,4,0),"") -> м | H17: =IFERROR(VLOOKUP(D17,'ВИС-2026'!$E$17:$K$2649,7,0),"") -> 6.28 | I17: =IFERROR(H17*G17,"") -> 0 | J17: =IFERROR((IF(H17="","",H17-H17*$D$7)),"") -> 6.28 | K17: =IFERROR(J17*G17, "") -> 0 | L17: =IFERROR(J17*$D$8, "") -> 0 | M17: =IFERROR(L17*G17, "") -> 0
F18: =IFERROR(VLOOKUP(D18,'ВИС-2026'!$E$17:$H$2115,5,0),"") | H18: =IFERROR(VLOOKUP(D18,'ВИС-2026'!$E$17:$K$2649,8,0),"") | I18: =IFERROR(H18*G18,"") | J18: =IFERROR((IF(H18="","",H18-H18*$D$7)),"") | K18: =IFERROR(J18*G18, "") | L18: =IFERROR(J18*$D$8, "") | M18: =IFERROR(L18*G18, "")
B19: N | C19: RAUTITAN | D19: 11301213100 | E19: =IFERROR(VLOOKUP(D19,'ВИС-2026'!$E$17:$H$2115,2,0),"") -> Универсальн.труба РЕХАУ STABIL 16,2х2,6 мм, бухта 100 м | F19: =IFERROR(VLOOKUP(D19,'ВИС-2026'!$E$17:$H$2115,4,0),"") -> м | H19: =IFERROR(VLOOKUP(D19,'ВИС-2026'!$E$17:$K$2649,7,0),"") -> 4.75 | I19: =IFERROR(H19*G19,"") -> 0 | J19: =IFERROR((IF(H19="","",H19-H19*$D$7)),"") -> 4.75 | K19: =IFERROR(J19*G19, "") -> 0 | L19: =IFERROR(J19*$D$8, "") -> 0 | M19: =IFERROR(L19*G19, "") -> 0
B20: N | C20: RAUTITAN | D20: 11301313100 | E20: =IFERROR(VLOOKUP(D20,'ВИС-2026'!$E$17:$H$2115,2,0),"") -> Универсальн.труба РЕХАУ STABIL 20х2,9 мм, бухта 100 м | F20: =IFERROR(VLOOKUP(D20,'ВИС-2026'!$E$17:$H$2115,4,0),"") -> м | H20: =IFERROR(VLOOKUP(D20,'ВИС-2026'!$E$17:$K$2649,7,0),"") -> 6.75 | I20: =IFERROR(H20*G20,"") -> 0 | J20: =IFERROR((IF(H20="","",H20-H20*$D$7)),"") -> 6.75 | K20: =IFERROR(J20*G20, "") -> 0 | L20: =IFERROR(J20*$D$8, "") -> 0 | M20: =IFERROR(L20*G20, "") -> 0
B21: N | C21: RAUTITAN | D21: 11301413050 | E21: =IFERROR(VLOOKUP(D21,'ВИС-2026'!$E$17:$H$2115,2,0),"") -> Универсальн.труба РЕХАУ STABIL 25х3,7 мм, бухта 50 м | F21: =IFERROR(VLOOKUP(D21,'ВИС-2026'!$E$17:$H$2115,4,0),"") -> м | H21: =IFERROR(VLOOKUP(D21,'ВИС-2026'!$E$17:$K$2649,7,0),"") -> 12.16 | I21: =IFERROR(H21*G21,"") -> 0 | J21: =IFERROR((IF(H21="","",H21-H21*$D$7)),"") -> 12.16 | K21: =IFERROR(J21*G21, "") -> 0 | L21: =IFERROR(J21*$D$8, "") -> 0 | M21: =IFERROR(L21*G21, "") -> 0
B22: N | C22: RAUTITAN | D22: 11301513025 | E22: =IFERROR(VLOOKUP(D22,'ВИС-2026'!$E$17:$H$2115,2,0),"") -> Универсальн.труба РЕХАУ STABIL 32х4,7 мм, бухта 25 м | F22: =IFERROR(VLOOKUP(D22,'ВИС-2026'!$E$17:$H$2115,4,0),"") -> м | H22: =IFERROR(VLOOKUP(D22,'ВИС-2026'!$E$17:$K$2649,7,0),"") -> 14.35 | I22: =IFERROR(H22*G22,"") -> 0 | J22: =IFERROR((IF(H22="","",H22-H22*$D$7)),"") -> 14.35 | K22: =IFERROR(J22*G22, "") -> 0 | L22: =IFERROR(J22*$D$8, "") -> 0 | M22: =IFERROR(L22*G22, "") -> 0
B23: N | C23: RAUTITAN | D23: 11301113005 | E23: =IFERROR(VLOOKUP(D23,'ВИС-2026'!$E$17:$H$2115,2,0),"") -> Универсальн.труба РЕХАУ STABIL 40х6,0 мм, прям.отрезки 5м | F23: =IFERROR(VLOOKUP(D23,'ВИС-2026'!$E$17:$H$2115,4,0),"") -> м | H23: =IFERROR(VLOOKUP(D23,'ВИС-2026'!$E$17:$K$2649,7,0),"") -> 38.05 | I23: =IFERROR(H23*G23,"") -> 0 | J23: =IFERROR((IF(H23="","",H23-H23*$D$7)),"") -> 38.05 | K23: =IFERROR(J23*G23, "") -> 0 | L23: =IFERROR(J23*$D$8, "") -> 0 | M23: =IFERROR(L23*G23, "") -> 0
E24: =IFERROR(VLOOKUP(D24,'ВИС-2026'!$E$17:$H$2115,2,0),"") | F24: =IFERROR(VLOOKUP(D24,'ВИС-2026'!$E$17:$H$2115,5,0),"") | H24: =IFERROR(VLOOKUP(D24,'ВИС-2026'!$E$17:$K$2649,8,0),"") | I24: =IFERROR(H24*G24,"") | J24: =IFERROR((IF(H24="","",H24-H24*$D$7)),"") | K24: =IFERROR(J24*G24, "") | L24: =IFERROR(J24*$D$8, "") | M24: =IFERROR(L24*G24, "")
B25: N | C25: RAUTITAN | D25: 11303703100 | E25: =IFERROR(VLOOKUP(D25,'ВИС-2026'!$E$17:$H$2115,2,0),"") -> Универсальн.труба РЕХАУ FLEX 16x2,2, бухта 100м | F25: =IFERROR(VLOOKUP(D25,'ВИС-2026'!$E$17:$H$2115,4,0),"") -> м | H25: =IFERROR(VLOOKUP(D25,'ВИС-2026'!$E$17:$K$2649,7,0),"") -> 2.49 | I25: =IFERROR(H25*G25,"") -> 0 | J25: =IFERROR((IF(H25="","",H25-H25*$D$7)),"") -> 2.49 | K25: =IFERROR(J25*G25, "") -> 0 | L25: =IFERROR(J25*$D$8, "") -> 0 | M25: =IFERROR(L25*G25, "") -> 0
B26: N | C26: RAUTITAN | D26: 11303803100 | E26: =IFERROR(VLOOKUP(D26,'ВИС-2026'!$E$17:$H$2115,2,0),"") -> Универсальн.труба РЕХАУ FLEX 20x2,8, бухта 100м | F26: =IFERROR(VLOOKUP(D26,'ВИС-2026'!$E$17:$H$2115,4,0),"") -> м | H26: =IFERROR(VLOOKUP(D26,'ВИС-2026'!$E$17:$K$2649,7,0),"") -> 3.72 | I26: =IFERROR(H26*G26,"") -> 0 | J26: =IFERROR((IF(H26="","",H26-H26*$D$7)),"") -> 3.72 | K26: =IFERROR(J26*G26, "") -> 0 | L26: =IFERROR(J26*$D$8, "") -> 0 | M26: =IFERROR(L26*G26, "") -> 0
B27: N | C27: RAUTITAN | D27: 11303903050 | E27: =IFERROR(VLOOKUP(D27,'ВИС-2026'!$E$17:$H$2115,2,0),"") -> Универсальн.труба РЕХАУ FLEX 25x3,5, бухта 50м | F27: =IFERROR(VLOOKUP(D27,'ВИС-2026'!$E$17:$H$2115,4,0),"") -> м | H27: =IFERROR(VLOOKUP(D27,'ВИС-2026'!$E$17:$K$2649,7,0),"") -> 5.77 | I27: =IFERROR(H27*G27,"") -> 0 | J27: =IFERROR((IF(H27="","",H27-H27*$D$7)),"") -> 5.77 | K27: =IFERROR(J27*G27, "") -> 0 | L27: =IFERROR(J27*$D$8, "") -> 0 | M27: =IFERROR(L27*G27, "") -> 0
B28: N | C28: RAUTITAN | D28: 11304003050 | E28: =IFERROR(VLOOKUP(D28,'ВИС-2026'!$E$17:$H$2115,2,0),"") -> Универсальн.труба РЕХАУ FLEX 32x4,4, бухта 50м | F28: =IFERROR(VLOOKUP(D28,'ВИС-2026'!$E$17:$H$2115,4,0),"") -> м | H28: =IFERROR(VLOOKUP(D28,'ВИС-2026'!$E$17:$K$2649,7,0),"") -> 9.38 | I28: =IFERROR(H28*G28,"") -> 0 | J28: =IFERROR((IF(H28="","",H28-H28*$D$7)),"") -> 9.38 | K28: =IFERROR(J28*G28, "") -> 0 | L28: =IFERROR(J28*$D$8, "") -> 0 | M28: =IFERROR(L28*G28, "") -> 0
B29: N | C29: RAUTITAN | D29: 11304113006 | E29: =IFERROR(VLOOKUP(D29,'ВИС-2026'!$E$17:$H$2115,2,0),"") -> Универсальн.труба РЕХАУ FLEX 40x5,5, прям.отрезки 6м | F29: =IFERROR(VLOOKUP(D29,'ВИС-2026'!$E$17:$H$2115,4,0),"") -> м | H29: =IFERROR(VLOOKUP(D29,'ВИС-2026'!$E$17:$K$2649,7,0),"") -> 18.2 | I29: =IFERROR(H29*G29,"") -> 0 | J29: =IFERROR((IF(H29="","",H29-H29*$D$7)),"") -> 18.2 | K29: =IFERROR(J29*G29, "") -> 0 | L29: =IFERROR(J29*$D$8, "") -> 0 | M29: =IFERROR(L29*G29, "") -> 0
B30: N | C30: RAUTITAN | D30: 11304213006 | E30: =IFERROR(VLOOKUP(D30,'ВИС-2026'!$E$17:$H$2115,2,0),"") -> Универсальн.труба РЕХАУ FLEX 50x6,9, прям.отрезки 6м | F30: =IFERROR(VLOOKUP(D30,'ВИС-2026'!$E$17:$H$2115,4,0),"") -> м | H30: =IFERROR(VLOOKUP(D30,'ВИС-2026'!$E$17:$K$2649,7,0),"") -> 23.95 | I30: =IFERROR(H30*G30,"") -> 0 | J30: =IFERROR((IF(H30="","",H30-H30*$D$7)),"") -> 23.95 | K30: =IFERROR(J30*G30, "") -> 0 | L30: =IFERROR(J30*$D$8, "") -> 0 | M30: =IFERROR(L30*G30, "") -> 0
B31: N | C31: RAUTITAN | D31: 11304313006 | E31: =IFERROR(VLOOKUP(D31,'ВИС-2026'!$E$17:$H$2115,2,0),"") -> Универсальн.труба РЕХАУ FLEX 63x8,6, прям.отрезки 6м | F31: =IFERROR(VLOOKUP(D31,'ВИС-2026'!$E$17:$H$2115,4,0),"") -> м | H31: =IFERROR(VLOOKUP(D31,'ВИС-2026'!$E$17:$K$2649,7,0),"") -> 35.34 | I31: =IFERROR(H31*G31,"") -> 0 | J31: =IFERROR((IF(H31="","",H31-H31*$D$7)),"") -> 35.34 | K31: =IFERROR(J31*G31, "") -> 0 | L31: =IFERROR(J31*$D$8, "") -> 0 | M31: =IFERROR(L31*G31, "") -> 0
E32: =IFERROR(VLOOKUP(D32,'ВИС-2026'!$E$17:$H$2115,2,0),"") | F32: =IFERROR(VLOOKUP(D32,'ВИС-2026'!$E$17:$H$2115,5,0),"") | H32: =IFERROR(VLOOKUP(D32,'ВИС-2026'!$E$17:$K$2649,8,0),"") | I32: =IFERROR(H32*G32,"") | J32: =IFERROR((IF(H32="","",H32-H32*$D$7)),"") | K32: =IFERROR(J32*G32, "") | L32: =IFERROR(J32*$D$8, "") | M32: =IFERROR(L32*G32, "")
B33: N | C33: RAUTITAN | D33: 11360423120 | E33: =IFERROR(VLOOKUP(D33,'ВИС-2026'!$E$17:$H$2115,2,0),"") -> Отоп. труба РЕХАУ PINK 16х2,2 мм, бухта 120 м | F33: =IFERROR(VLOOKUP(D33,'ВИС-2026'!$E$17:$H$2115,4,0),"") -> м | H33: =IFERROR(VLOOKUP(D33,'ВИС-2026'!$E$17:$K$2649,7,0),"") -> 2.38 | I33: =IFERROR(H33*G33,"") -> 0 | J33: =IFERROR((IF(H33="","",H33-H33*$D$7)),"") -> 2.38 | K33: =IFERROR(J33*G33, "") -> 0 | L33: =IFERROR(J33*$D$8, "") -> 0 | M33: =IFERROR(L33*G33, "") -> 0
B34: N | C34: RAUTITAN | D34: 11360523120 | E34: =IFERROR(VLOOKUP(D34,'ВИС-2026'!$E$17:$H$2115,2,0),"") -> Отоп. труба РЕХАУ PINK 20х2,8 мм, бухта 120 м | F34: =IFERROR(VLOOKUP(D34,'ВИС-2026'!$E$17:$H$2115,4,0),"") -> м | H34: =IFERROR(VLOOKUP(D34,'ВИС-2026'!$E$17:$K$2649,7,0),"") -> 3.46 | I34: =IFERROR(H34*G34,"") -> 0 | J34: =IFERROR((IF(H34="","",H34-H34*$D$7)),"") -> 3.46 | K34: =IFERROR(J34*G34, "") -> 0 | L34: =IFERROR(J34*$D$8, "") -> 0 | M34: =IFERROR(L34*G34, "") -> 0
B35: N | C35: RAUTITAN | D35: 11360623050 | E35: =IFERROR(VLOOKUP(D35,'ВИС-2026'!$E$17:$H$2115,2,0),"") -> Отоп. труба РЕХАУ PINK 25х3,5 мм, бухта 50 м | F35: =IFERROR(VLOOKUP(D35,'ВИС-2026'!$E$17:$H$2115,4,0),"") -> м | H35: =IFERROR(VLOOKUP(D35,'ВИС-2026'!$E$17:$K$2649,7,0),"") -> 5.37 | I35: =IFERROR(H35*G35,"") -> 0 | J35: =IFERROR((IF(H35="","",H35-H35*$D$7)),"") -> 5.37 | K35: =IFERROR(J35*G35, "") -> 0 | L35: =IFERROR(J35*$D$8, "") -> 0 | M35: =IFERROR(L35*G35, "") -> 0
B36: N | C36: RAUTITAN | D36: 11360723050 | E36: =IFERROR(VLOOKUP(D36,'ВИС-2026'!$E$17:$H$2115,2,0),"") -> Отоп. труба РЕХАУ PINK 32х4,4 мм, бухта 50 м | F36: =IFERROR(VLOOKUP(D36,'ВИС-2026'!$E$17:$H$2115,4,0),"") -> м | H36: =IFERROR(VLOOKUP(D36,'ВИС-2026'!$E$17:$K$2649,7,0),"") -> 8.72 | I36: =IFERROR(H36*G36,"") -> 0 | J36: =IFERROR((IF(H36="","",H36-H36*$D$7)),"") -> 8.72 | K36: =IFERROR(J36*G36, "") -> 0 | L36: =IFERROR(J36*$D$8, "") -> 0 | M36: =IFERROR(L36*G36, "") -> 0
E37: =IFERROR(VLOOKUP(D37,'ВИС-2026'!$E$17:$H$2115,2,0),"") | F37: =IFERROR(VLOOKUP(D37,'ВИС-2026'!$E$17:$H$2115,5,0),"") | H37: =IFERROR(VLOOKUP(D37,'ВИС-2026'!$E$17:$K$2649,8,0),"") | I37: =IFERROR(H37*G37,"") | J37: =IFERROR((IF(H37="","",H37-H37*$D$7)),"") | K37: =IFERROR(J37*G37, "") | L37: =IFERROR(J37*$D$8, "") | M37: =IFERROR(L37*G37, "")
B38: N | C38: RAUTITAN | D38: 11331703200 | E38: =IFERROR(VLOOKUP(D38,'ВИС-2026'!$E$17:$H$2115,2,0),"") -> Универсальн. объектная труба РЕХАУ BLACK 16х2,2 мм, бухта 200 м | F38: =IFERROR(VLOOKUP(D38,'ВИС-2026'!$E$17:$H$2115,4,0),"") -> м | H38: =IFERROR(VLOOKUP(D38,'ВИС-2026'!$E$17:$K$2649,7,0),"") -> 0 | I38: =IFERROR(H38*G38,"") -> 0 | J38: =IFERROR((IF(H38="","",H38-H38*$D$7)),"") -> 0 | K38: =IFERROR(J38*G38, "") -> 0 | L38: =IFERROR(J38*$D$8, "") -> 0 | M38: =IFERROR(L38*G38, "") -> 0
B39: N | C39: RAUTITAN | D39: 11331803180 | E39: =IFERROR(VLOOKUP(D39,'ВИС-2026'!$E$17:$H$2115,2,0),"") -> Универсальн. объектная труба РЕХАУ BLACK 20х2,8 мм, бухта 180 м | F39: =IFERROR(VLOOKUP(D39,'ВИС-2026'!$E$17:$H$2115,4,0),"") -> м | H39: =IFERROR(VLOOKUP(D39,'ВИС-2026'!$E$17:$K$2649,7,0),"") -> 0 | I39: =IFERROR(H39*G39,"") -> 0 | J39: =IFERROR((IF(H39="","",H39-H39*$D$7)),"") -> 0 | K39: =IFERROR(J39*G39, "") -> 0 | L39: =IFERROR(J39*$D$8, "") -> 0 | M39: =IFERROR(L39*G39, "") -> 0
B40: N | C40: RAUTITAN | D40: 11331903100 | E40: =IFERROR(VLOOKUP(D40,'ВИС-2026'!$E$17:$H$2115,2,0),"") -> Универсальн. объектная труба РЕХАУ BLACK 25х3,5 мм, бухта 100 м | F40: =IFERROR(VLOOKUP(D40,'ВИС-2026'!$E$17:$H$2115,4,0),"") -> м | H40: =IFERROR(VLOOKUP(D40,'ВИС-2026'!$E$17:$K$2649,7,0),"") -> 0 | I40: =IFERROR(H40*G40,"") -> 0 | J40: =IFERROR((IF(H40="","",H40-H40*$D$7)),"") -> 0 | K40: =IFERROR(J40*G40, "") -> 0 | L40: =IFERROR(J40*$D$8, "") -> 0 | M40: =IFERROR(L40*G40, "") -> 0
E41: =IFERROR(VLOOKUP(D41,'ВИС-2026'!$E$17:$H$2115,2,0),"") | F41: =IFERROR(VLOOKUP(D41,'ВИС-2026'!$E$17:$H$2115,5,0),"") | H41: =IFERROR(VLOOKUP(D41,'ВИС-2026'!$E$17:$K$2649,8,0),"") | I41: =IFERROR(H41*G41,"") | J41: =IFERROR((IF(H41="","",H41-H41*$D$7)),"") | K41: =IFERROR(J41*G41, "") | L41: =IFERROR(J41*$D$8, "") | M41: =IFERROR(L41*G41, "")
B42: N | C42: RAUTITAN | D42: 11380333001 | E42: =IFERROR(VLOOKUP(D42,'ВИС-2026'!$E$17:$H$2115,2,0),"") -> Фиксирующий желоб РЕХАУ для ПЭ-трубы 16/17 | F42: =IFERROR(VLOOKUP(D42,'ВИС-2026'!$E$17:$H$2115,4,0),"") -> м | H42: =IFERROR(VLOOKUP(D42,'ВИС-2026'!$E$17:$K$2649,7,0),"") -> 2.6 | I42: =IFERROR(H42*G42,"") -> 0 | J42: =IFERROR((IF(H42="","",H42-H42*$D$7)),"") -> 2.6 | K42: =IFERROR(J42*G42, "") -> 0 | L42: =IFERROR(J42*$D$8, "") -> 0 | M42: =IFERROR(L42*G42, "") -> 0
B43: N | C43: RAUTITAN | D43: 11380433001 | E43: =IFERROR(VLOOKUP(D43,'ВИС-2026'!$E$17:$H$2115,2,0),"") -> Фиксирующий желоб РЕХАУ для ПЭ-трубы 20 | F43: =IFERROR(VLOOKUP(D43,'ВИС-2026'!$E$17:$H$2115,4,0),"") -> м | H43: =IFERROR(VLOOKUP(D43,'ВИС-2026'!$E$17:$K$2649,7,0),"") -> 2.82 | I43: =IFERROR(H43*G43,"") -> 0 | J43: =IFERROR((IF(H43="","",H43-H43*$D$7)),"") -> 2.82 | K43: =IFERROR(J43*G43, "") -> 0 | L43: =IFERROR(J43*$D$8, "") -> 0 | M43: =IFERROR(L43*G43, "") -> 0
...
